Workbook

Sheet Uitleg
A1: Trainingsschema Antwerp 10 Miles – zondag 25 april 2027
A2: Voor James · 27 weken (19 okt 2026 – 25 apr 2027) · lopen gecombineerd met pendelen naar Gent
A4: Doel
A5: Vorige tijd (2026) | B5: 1:27:22 – 5:26/km
A6: Doeltijd 2027 | B6: 1:25:00 – 5:17/km
A7: Ambitieus (als alles meezit) | B7: 1:22:00 – 5:06/km
A8: Checkpoint | B8: Testloop 10 km op zo 4 april: onder 52:00 → 1:25 realistisch; onder 50:30 → mik op 1:22
A10: Weekstructuur
A11: Dag | B11: Fase 1 (wk 1–12) | C11: Fase 2–3 (wk 13–25) | D11: Waarom
A12: Maandag | B12: Rustige loop | C12: Rustige loop | D12: Herstel na de lange duurloop
A13: Dinsdag | B13: Pendel fiets | C13: Pendel fiets | D13: Aerobe basis zonder impact op pezen
A14: Woensdag | B14: Rustig + strides / fartlek | C14: Tempo (fase 2) / intervallen (fase 3) | D14: De kwaliteitstraining; nooit op een pendeldag
A15: Donderdag | B15: Kracht | C15: Rustige loop + kracht | D15: Kracht direct na een rustige loop
A16: Vrijdag | B16: Pendel fiets | C16: Pendel fiets | D16: Rustig, benen fris houden voor zondag
A17: Zaterdag | B17: Kracht (+ optioneel rustige rit) | C17: Kracht of rust | D17: Rust in herstelweken
A18: Zondag | B18: Lange duurloop | C18: Lange duurloop (soms met wedstrijdtempo) | D18: Belangrijkste training van de week
A19: Herstelweken: week 4, 8, 12, 16, 20 en 24 (minder volume, geen kwaliteit). Pendel je op andere dagen? Schuif zo dat er nooit een kwaliteitstraining op een pendeldag valt.
A21: Zones om in Polar Flow in te stellen (sportprofiel Hardlopen)
A22: Zone | B22: Hartslag (bpm) | C22: Tempo (min/km) | D22: Gebruik
A23: Zone 1 | B23: 105–124 | C23: trager dan 7:00 | D23: Opwarmen, herstel, joggen tussen intervallen
A24: Zone 2 | B24: 125–137 | C24: 6:15–7:00 | D24: Rustige lopen en lange duurlopen (±80% van alles)
A25: Zone 3 | B25: 138–146 | C25: 5:35–6:15 | D25: Grijze zone – zo weinig mogelijk
A26: Zone 4 | B26: 147–156 | C26: 5:08–5:35 | D26: Tempo, drempel en wedstrijdtempo (5:17)
A27: Zone 5 | B27: 157+ | C27: sneller dan 5:08 | D27: Intervallen van 1 km
A28: Gebaseerd op je Strava-data: rustige lopen op HR 125–135, Antwerp 10 Miles gemiddeld 154 / max 165. Je huidige Strava-zones (5 km in 29:09) zijn verouderd. Pas aan na de testloop.
A30: Zo zet je het op je Polar Pacer Pro
A31: 1. Ga in Polar Flow (web, flow.polar.com) naar Instellingen → Sportprofielen → Hardlopen en stel de hartslag- en tempozones hierboven in (vrije/handmatige zones).
A32: 2. Maak per training in de tab 'Polar trainingen' een favoriet: Favorieten → Trainingsdoel maken → 'Gefaseerd'. Gebruik exact de naam uit de tab en neem de fasen één op één over (afstand of tijd + zone). Herhalingen maak je met 'Herhalen'.
A33: 3. Begin met de trainingen van fase 1 (kolom 'Eerste keer'). Je hoeft niet alles vooraf aan te maken. Doe het per fase, ongeveer 6–10 favorieten.
A34: 4. Plan ze in: open je dagboek in Polar Flow, klik op de dag → Toevoegen → Trainingsdoel → kies de favoriet. Doe dit telkens 2 weken vooruit.
A35: 5. Synchroniseer je horloge. Op de Pacer Pro vind je de training van de dag bij het starten van een sessie (of via Favorieten). Het horloge begeleidt je fase per fase.
A36: 6. Wedstrijddag: gebruik de Race Pace-functie (16,1 km in 1:25:00) in plaats van een gefaseerd doel.
A37: Alternatief: met een betalend TrainingPeaks Premium-account kun je trainingen plannen en verslepen; die synchroniseren automatisch naar Polar Flow en je horloge (tot 14 dagen vooruit). Met een gratis account kun je zelf geen toekomstige trainingen plannen.
A39: Krachtroutine (±25', 2× per week)
A40: Oefening | B40: Sets × herhalingen | D40: Waarom
A41: Kuitheffing gestrekt been (op trede, excentrisch traag zakken) | B41: 3 × 15 per been | D41: Kuitblessure 2026: sterkere kuit en achillespees
A42: Kuitheffing gebogen knie (soleus) | B42: 3 × 15 per been | D42: Soleus draagt veel van de belasting bij lopen
A43: Nordic hamstring curl (of hamstringbrug op 1 been) | B43: 3 × 5–8 | D43: Hamstringblessure 2026
A44: Bulgarian split squat of goblet squat | B44: 3 × 10 per been | D44: Kracht en stabiliteit knie/heup
A45: Zijlig heupabductie of monster walk met band | B45: 3 × 15 | D45: Bekkenstabiliteit
...

Sheet Weekoverzicht
A1: Week | B1: Start (ma) | C1: Fase | D1: Herstelweek | E1: Gepland lopen (km) | F1: Langste loop (km) | G1: Kwaliteitstraining | H1: Gepland fietsen (km) | I1: Gelopen km (echt) | J1: % van plan | K1: Sessies gedaan | L1: Sessies gepland
A2: 1 | B2: 46314 | C2: 1 · Basis | E2: =SUMIFS(Dagschema!$H$2:$H$190,Dagschema!$C$2:$C$190,A2) -> 15 | F2: =_xlfn.MAXIFS(Dagschema!$H$2:$H$190,Dagschema!$C$2:$C$190,A2) -> 7 | G2: Rustig 4 km | H2: =SUMIFS(Dagschema!$I$2:$I$190,Dagschema!$C$2:$C$190,A2) -> 120 | I2: =SUMIFS(Dagschema!$K$2:$K$190,Dagschema!$C$2:$C$190,A2) -> 0 | J2: =IF(I2=0,"",I2/E2) | K2: =COUNTIFS(Dagschema!$C$2:$C$190,A2,Dagschema!$J$2:$J$190,"x") -> 0 | L2: =COUNTIFS(Dagschema!$C$2:$C$190,A2,Dagschema!$E$2:$E$190,"<>Rust") -> 7
A3: 2 | B3: 46321 | C3: 1 · Basis | E3: =SUMIFS(Dagschema!$H$2:$H$190,Dagschema!$C$2:$C$190,A3) -> 17.3 | F3: =_xlfn.MAXIFS(Dagschema!$H$2:$H$190,Dagschema!$C$2:$C$190,A3) -> 8 | G3: Rustig 5 km + strides | H3: =SUMIFS(Dagschema!$I$2:$I$190,Dagschema!$C$2:$C$190,A3) -> 120 | I3: =SUMIFS(Dagschema!$K$2:$K$190,Dagschema!$C$2:$C$190,A3) -> 0 | J3: =IF(I3=0,"",I3/E3) | K3: =COUNTIFS(Dagschema!$C$2:$C$190,A3,Dagschema!$J$2:$J$190,"x") -> 0 | L3: =COUNTIFS(Dagschema!$C$2:$C$190,A3,Dagschema!$E$2:$E$190,"<>Rust") -> 7
A4: 3 | B4: 46328 | C4: 1 · Basis | E4: =SUMIFS(Dagschema!$H$2:$H$190,Dagschema!$C$2:$C$190,A4) -> 19.3 | F4: =_xlfn.MAXIFS(Dagschema!$H$2:$H$190,Dagschema!$C$2:$C$190,A4) -> 9 | G4: Rustig 5 km + strides | H4: =SUMIFS(Dagschema!$I$2:$I$190,Dagschema!$C$2:$C$190,A4) -> 120 | I4: =SUMIFS(Dagschema!$K$2:$K$190,Dagschema!$C$2:$C$190,A4) -> 0 | J4: =IF(I4=0,"",I4/E4) | K4: =COUNTIFS(Dagschema!$C$2:$C$190,A4,Dagschema!$J$2:$J$190,"x") -> 0 | L4: =COUNTIFS(Dagschema!$C$2:$C$190,A4,Dagschema!$E$2:$E$190,"<>Rust") -> 7
A5: 4 | B5: 46335 | C5: 1 · Basis | D5: ja | E5: =SUMIFS(Dagschema!$H$2:$H$190,Dagschema!$C$2:$C$190,A5) -> 15 | F5: =_xlfn.MAXIFS(Dagschema!$H$2:$H$190,Dagschema!$C$2:$C$190,A5) -> 7 | G5: Rustig 4 km | H5: =SUMIFS(Dagschema!$I$2:$I$190,Dagschema!$C$2:$C$190,A5) -> 120 | I5: =SUMIFS(Dagschema!$K$2:$K$190,Dagschema!$C$2:$C$190,A5) -> 0 | J5: =IF(I5=0,"",I5/E5) | K5: =COUNTIFS(Dagschema!$C$2:$C$190,A5,Dagschema!$J$2:$J$190,"x") -> 0 | L5: =COUNTIFS(Dagschema!$C$2:$C$190,A5,Dagschema!$E$2:$E$190,"<>Rust") -> 6
A6: 5 | B6: 46342 | C6: 1 · Basis | E6: =SUMIFS(Dagschema!$H$2:$H$190,Dagschema!$C$2:$C$190,A6) -> 21.3 | F6: =_xlfn.MAXIFS(Dagschema!$H$2:$H$190,Dagschema!$C$2:$C$190,A6) -> 10 | G6: Rustig 6 km + strides | H6: =SUMIFS(Dagschema!$I$2:$I$190,Dagschema!$C$2:$C$190,A6) -> 120 | I6: =SUMIFS(Dagschema!$K$2:$K$190,Dagschema!$C$2:$C$190,A6) -> 0 | J6: =IF(I6=0,"",I6/E6) | K6: =COUNTIFS(Dagschema!$C$2:$C$190,A6,Dagschema!$J$2:$J$190,"x") -> 0 | L6: =COUNTIFS(Dagschema!$C$2:$C$190,A6,Dagschema!$E$2:$E$190,"<>Rust") -> 7
A7: 6 | B7: 46349 | C7: 1 · Basis | E7: =SUMIFS(Dagschema!$H$2:$H$190,Dagschema!$C$2:$C$190,A7) -> 22 | F7: =_xlfn.MAXIFS(Dagschema!$H$2:$H$190,Dagschema!$C$2:$C$190,A7) -> 11 | G7: Fartlek 8×1' (6 km) | H7: =SUMIFS(Dagschema!$I$2:$I$190,Dagschema!$C$2:$C$190,A7) -> 120 | I7: =SUMIFS(Dagschema!$K$2:$K$190,Dagschema!$C$2:$C$190,A7) -> 0 | J7: =IF(I7=0,"",I7/E7) | K7: =COUNTIFS(Dagschema!$C$2:$C$190,A7,Dagschema!$J$2:$J$190,"x") -> 0 | L7: =COUNTIFS(Dagschema!$C$2:$C$190,A7,Dagschema!$E$2:$E$190,"<>Rust") -> 7
A8: 7 | B8: 46356 | C8: 1 · Basis | E8: =SUMIFS(Dagschema!$H$2:$H$190,Dagschema!$C$2:$C$190,A8) -> 25 | F8: =_xlfn.MAXIFS(Dagschema!$H$2:$H$190,Dagschema!$C$2:$C$190,A8) -> 12 | G8: Fartlek 8×1' (7 km) | H8: =SUMIFS(Dagschema!$I$2:$I$190,Dagschema!$C$2:$C$190,A8) -> 120 | I8: =SUMIFS(Dagschema!$K$2:$K$190,Dagschema!$C$2:$C$190,A8) -> 0 | J8: =IF(I8=0,"",I8/E8) | K8: =COUNTIFS(Dagschema!$C$2:$C$190,A8,Dagschema!$J$2:$J$190,"x") -> 0 | L8: =COUNTIFS(Dagschema!$C$2:$C$190,A8,Dagschema!$E$2:$E$190,"<>Rust") -> 7
A9: 8 | B9: 46363 | C9: 1 · Basis | D9: ja | E9: =SUMIFS(Dagschema!$H$2:$H$190,Dagschema!$C$2:$C$190,A9) -> 19.3 | F9: =_xlfn.MAXIFS(Dagschema!$H$2:$H$190,Dagschema!$C$2:$C$190,A9) -> 9 | G9: Rustig 5 km + strides | H9: =SUMIFS(Dagschema!$I$2:$I$190,Dagschema!$C$2:$C$190,A9) -> 120 | I9: =SUMIFS(Dagschema!$K$2:$K$190,Dagschema!$C$2:$C$190,A9) -> 0 | J9: =IF(I9=0,"",I9/E9) | K9: =COUNTIFS(Dagschema!$C$2:$C$190,A9,Dagschema!$J$2:$J$190,"x") -> 0 | L9: =COUNTIFS(Dagschema!$C$2:$C$190,A9,Dagschema!$E$2:$E$190,"<>Rust") -> 6
A10: 9 | B10: 46370 | C10: 1 · Basis | E10: =SUMIFS(Dagschema!$H$2:$H$190,Dagschema!$C$2:$C$190,A10) -> 25 | F10: =_xlfn.MAXIFS(Dagschema!$H$2:$H$190,Dagschema!$C$2:$C$190,A10) -> 12 | G10: Fartlek 8×1' (7 km) | H10: =SUMIFS(Dagschema!$I$2:$I$190,Dagschema!$C$2:$C$190,A10) -> 120 | I10: =SUMIFS(Dagschema!$K$2:$K$190,Dagschema!$C$2:$C$190,A10) -> 0 | J10: =IF(I10=0,"",I10/E10) | K10: =COUNTIFS(Dagschema!$C$2:$C$190,A10,Dagschema!$J$2:$J$190,"x") -> 0 | L10: =COUNTIFS(Dagschema!$C$2:$C$190,A10,Dagschema!$E$2:$E$190,"<>Rust") -> 7
A11: 10 | B11: 46377 | C11: 1 · Basis | E11: =SUMIFS(Dagschema!$H$2:$H$190,Dagschema!$C$2:$C$190,A11) -> 27 | F11: =_xlfn.MAXIFS(Dagschema!$H$2:$H$190,Dagschema!$C$2:$C$190,A11) -> 13 | G11: Fartlek 8×1' (7 km) | H11: =SUMIFS(Dagschema!$I$2:$I$190,Dagschema!$C$2:$C$190,A11) -> 120 | I11: =SUMIFS(Dagschema!$K$2:$K$190,Dagschema!$C$2:$C$190,A11) -> 0 | J11: =IF(I11=0,"",I11/E11) | K11: =COUNTIFS(Dagschema!$C$2:$C$190,A11,Dagschema!$J$2:$J$190,"x") -> 0 | L11: =COUNTIFS(Dagschema!$C$2:$C$190,A11,Dagschema!$E$2:$E$190,"<>Rust") -> 7
A12: 11 | B12: 46384 | C12: 1 · Basis | E12: =SUMIFS(Dagschema!$H$2:$H$190,Dagschema!$C$2:$C$190,A12) -> 26.3 | F12: =_xlfn.MAXIFS(Dagschema!$H$2:$H$190,Dagschema!$C$2:$C$190,A12) -> 13 | G12: Rustig 7 km + strides | H12: =SUMIFS(Dagschema!$I$2:$I$190,Dagschema!$C$2:$C$190,A12) -> 120 | I12: =SUMIFS(Dagschema!$K$2:$K$190,Dagschema!$C$2:$C$190,A12) -> 0 | J12: =IF(I12=0,"",I12/E12) | K12: =COUNTIFS(Dagschema!$C$2:$C$190,A12,Dagschema!$J$2:$J$190,"x") -> 0 | L12: =COUNTIFS(Dagschema!$C$2:$C$190,A12,Dagschema!$E$2:$E$190,"<>Rust") -> 7
A13: 12 | B13: 46391 | C13: 1 · Basis | D13: ja | E13: =SUMIFS(Dagschema!$H$2:$H$190,Dagschema!$C$2:$C$190,A13) -> 21.3 | F13: =_xlfn.MAXIFS(Dagschema!$H$2:$H$190,Dagschema!$C$2:$C$190,A13) -> 10 | G13: Rustig 6 km + strides | H13: =SUMIFS(Dagschema!$I$2:$I$190,Dagschema!$C$2:$C$190,A13) -> 120 | I13: =SUMIFS(Dagschema!$K$2:$K$190,Dagschema!$C$2:$C$190,A13) -> 0 | J13: =IF(I13=0,"",I13/E13) | K13: =COUNTIFS(Dagschema!$C$2:$C$190,A13,Dagschema!$J$2:$J$190,"x") -> 0 | L13: =COUNTIFS(Dagschema!$C$2:$C$190,A13,Dagschema!$E$2:$E$190,"<>Rust") -> 6
A14: 13 | B14: 46398 | C14: 2 · Opbouw | E14: =SUMIFS(Dagschema!$H$2:$H$190,Dagschema!$C$2:$C$190,A14) -> 28 | F14: =_xlfn.MAXIFS(Dagschema!$H$2:$H$190,Dagschema!$C$2:$C$190,A14) -> 12 | G14: Tempo 3×6' | H14: =SUMIFS(Dagschema!$I$2:$I$190,Dagschema!$C$2:$C$190,A14) -> 120 | I14: =SUMIFS(Dagschema!$K$2:$K$190,Dagschema!$C$2:$C$190,A14) -> 0 | J14: =IF(I14=0,"",I14/E14) | K14: =COUNTIFS(Dagschema!$C$2:$C$190,A14,Dagschema!$J$2:$J$190,"x") -> 0 | L14: =COUNTIFS(Dagschema!$C$2:$C$190,A14,Dagschema!$E$2:$E$190,"<>Rust") -> 7
A15: 14 | B15: 46405 | C15: 2 · Opbouw | E15: =SUMIFS(Dagschema!$H$2:$H$190,Dagschema!$C$2:$C$190,A15) -> 31 | F15: =_xlfn.MAXIFS(Dagschema!$H$2:$H$190,Dagschema!$C$2:$C$190,A15) -> 13 | G15: Tempo 3×8' | H15: =SUMIFS(Dagschema!$I$2:$I$190,Dagschema!$C$2:$C$190,A15) -> 120 | I15: =SUMIFS(Dagschema!$K$2:$K$190,Dagschema!$C$2:$C$190,A15) -> 0 | J15: =IF(I15=0,"",I15/E15) | K15: =COUNTIFS(Dagschema!$C$2:$C$190,A15,Dagschema!$J$2:$J$190,"x") -> 0 | L15: =COUNTIFS(Dagschema!$C$2:$C$190,A15,Dagschema!$E$2:$E$190,"<>Rust") -> 7
A16: 15 | B16: 46412 | C16: 2 · Opbouw | E16: =SUMIFS(Dagschema!$H$2:$H$190,Dagschema!$C$2:$C$190,A16) -> 34 | F16: =_xlfn.MAXIFS(Dagschema!$H$2:$H$190,Dagschema!$C$2:$C$190,A16) -> 14 | G16: Tempo 3×10' | H16: =SUMIFS(Dagschema!$I$2:$I$190,Dagschema!$C$2:$C$190,A16) -> 120 | I16: =SUMIFS(Dagschema!$K$2:$K$190,Dagschema!$C$2:$C$190,A16) -> 0 | J16: =IF(I16=0,"",I16/E16) | K16: =COUNTIFS(Dagschema!$C$2:$C$190,A16,Dagschema!$J$2:$J$190,"x") -> 0 | L16: =COUNTIFS(Dagschema!$C$2:$C$190,A16,Dagschema!$E$2:$E$190,"<>Rust") -> 7
A17: 16 | B17: 46419 | C17: 2 · Opbouw | D17: ja | E17: =SUMIFS(Dagschema!$H$2:$H$190,Dagschema!$C$2:$C$190,A17) -> 26.3 | F17: =_xlfn.MAXIFS(Dagschema!$H$2:$H$190,Dagschema!$C$2:$C$190,A17) -> 11 | G17: Rustig 6 km + strides | H17: =SUMIFS(Dagschema!$I$2:$I$190,Dagschema!$C$2:$C$190,A17) -> 120 | I17: =SUMIFS(Dagschema!$K$2:$K$190,Dagschema!$C$2:$C$190,A17) -> 0 | J17: =IF(I17=0,"",I17/E17) | K17: =COUNTIFS(Dagschema!$C$2:$C$190,A17,Dagschema!$J$2:$J$190,"x") -> 0 | L17: =COUNTIFS(Dagschema!$C$2:$C$190,A17,Dagschema!$E$2:$E$190,"<>Rust") -> 6
A18: 17 | B18: 46426 | C18: 2 · Opbouw | E18: =SUMIFS(Dagschema!$H$2:$H$190,Dagschema!$C$2:$C$190,A18) -> 37 | F18: =_xlfn.MAXIFS(Dagschema!$H$2:$H$190,Dagschema!$C$2:$C$190,A18) -> 15 | G18: Tempo 2×15' | H18: =SUMIFS(Dagschema!$I$2:$I$190,Dagschema!$C$2:$C$190,A18) -> 120 | I18: =SUMIFS(Dagschema!$K$2:$K$190,Dagschema!$C$2:$C$190,A18) -> 0 | J18: =IF(I18=0,"",I18/E18) | K18: =COUNTIFS(Dagschema!$C$2:$C$190,A18,Dagschema!$J$2:$J$190,"x") -> 0 | L18: =COUNTIFS(Dagschema!$C$2:$C$190,A18,Dagschema!$E$2:$E$190,"<>Rust") -> 7
A19: 18 | B19: 46433 | C19: 2 · Opbouw | E19: =SUMIFS(Dagschema!$H$2:$H$190,Dagschema!$C$2:$C$190,A19) -> 38 | F19: =_xlfn.MAXIFS(Dagschema!$H$2:$H$190,Dagschema!$C$2:$C$190,A19) -> 15 | G19: Tempo 2×15' | H19: =SUMIFS(Dagschema!$I$2:$I$190,Dagschema!$C$2:$C$190,A19) -> 120 | I19: =SUMIFS(Dagschema!$K$2:$K$190,Dagschema!$C$2:$C$190,A19) -> 0 | J19: =IF(I19=0,"",I19/E19) | K19: =COUNTIFS(Dagschema!$C$2:$C$190,A19,Dagschema!$J$2:$J$190,"x") -> 0 | L19: =COUNTIFS(Dagschema!$C$2:$C$190,A19,Dagschema!$E$2:$E$190,"<>Rust") -> 7
A20: 19 | B20: 46440 | C20: 3 · Specifiek | E20: =SUMIFS(Dagschema!$H$2:$H$190,Dagschema!$C$2:$C$190,A20) -> 37.9 | F20: =_xlfn.MAXIFS(Dagschema!$H$2:$H$190,Dagschema!$C$2:$C$190,A20) -> 15 | G20: Interval 5×1 km | H20: =SUMIFS(Dagschema!$I$2:$I$190,Dagschema!$C$2:$C$190,A20) -> 120 | I20: =SUMIFS(Dagschema!$K$2:$K$190,Dagschema!$C$2:$C$190,A20) -> 0 | J20: =IF(I20=0,"",I20/E20) | K20: =COUNTIFS(Dagschema!$C$2:$C$190,A20,Dagschema!$J$2:$J$190,"x") -> 0 | L20: =COUNTIFS(Dagschema!$C$2:$C$190,A20,Dagschema!$E$2:$E$190,"<>Rust") -> 7
A21: 20 | B21: 46447 | C21: 3 · Specifiek | D21: ja | E21: =SUMIFS(Dagschema!$H$2:$H$190,Dagschema!$C$2:$C$190,A21) -> 29 | F21: =_xlfn.MAXIFS(Dagschema!$H$2:$H$190,Dagschema!$C$2:$C$190,A21) -> 12 | G21: Tempo 20' doorlopend | H21: =SUMIFS(Dagschema!$I$2:$I$190,Dagschema!$C$2:$C$190,A21) -> 120 | I21: =SUMIFS(Dagschema!$K$2:$K$190,Dagschema!$C$2:$C$190,A21) -> 0 | J21: =IF(I21=0,"",I21/E21) | K21: =COUNTIFS(Dagschema!$C$2:$C$190,A21,Dagschema!$J$2:$J$190,"x") -> 0 | L21: =COUNTIFS(Dagschema!$C$2:$C$190,A21,Dagschema!$E$2:$E$190,"<>Rust") -> 6
A22: 21 | B22: 46454 | C22: 3 · Specifiek | E22: =SUMIFS(Dagschema!$H$2:$H$190,Dagschema!$C$2:$C$190,A22) -> 41.2 | F22: =_xlfn.MAXIFS(Dagschema!$H$2:$H$190,Dagschema!$C$2:$C$190,A22) -> 16 | G22: Interval 6×1 km | H22: =SUMIFS(Dagschema!$I$2:$I$190,Dagschema!$C$2:$C$190,A22) -> 120 | I22: =SUMIFS(Dagschema!$K$2:$K$190,Dagschema!$C$2:$C$190,A22) -> 0 | J22: =IF(I22=0,"",I22/E22) | K22: =COUNTIFS(Dagschema!$C$2:$C$190,A22,Dagschema!$J$2:$J$190,"x") -> 0 | L22: =COUNTIFS(Dagschema!$C$2:$C$190,A22,Dagschema!$E$2:$E$190,"<>Rust") -> 7
A23: 22 | B23: 46461 | C23: 3 · Specifiek | E23: =SUMIFS(Dagschema!$H$2:$H$190,Dagschema!$C$2:$C$190,A23) -> 42.3 | F23: =_xlfn.MAXIFS(Dagschema!$H$2:$H$190,Dagschema!$C$2:$C$190,A23) -> 17 | G23: Interval 4×1600 m | H23: =SUMIFS(Dagschema!$I$2:$I$190,Dagschema!$C$2:$C$190,A23) -> 120 | I23: =SUMIFS(Dagschema!$K$2:$K$190,Dagschema!$C$2:$C$190,A23) -> 0 | J23: =IF(I23=0,"",I23/E23) | K23: =COUNTIFS(Dagschema!$C$2:$C$190,A23,Dagschema!$J$2:$J$190,"x") -> 0 | L23: =COUNTIFS(Dagschema!$C$2:$C$190,A23,Dagschema!$E$2:$E$190,"<>Rust") -> 7
A24: 23 | B24: 46468 | C24: 3 · Specifiek | E24: =SUMIFS(Dagschema!$H$2:$H$190,Dagschema!$C$2:$C$190,A24) -> 43.7 | F24: =_xlfn.MAXIFS(Dagschema!$H$2:$H$190,Dagschema!$C$2:$C$190,A24) -> 18 | G24: Interval 3×2 km | H24: =SUMIFS(Dagschema!$I$2:$I$190,Dagschema!$C$2:$C$190,A24) -> 120 | I24: =SUMIFS(Dagschema!$K$2:$K$190,Dagschema!$C$2:$C$190,A24) -> 0 | J24: =IF(I24=0,"",I24/E24) | K24: =COUNTIFS(Dagschema!$C$2:$C$190,A24,Dagschema!$J$2:$J$190,"x") -> 0 | L24: =COUNTIFS(Dagschema!$C$2:$C$190,A24,Dagschema!$E$2:$E$190,"<>Rust") -> 7
A25: 24 | B25: 46475 | C25: 3 · Specifiek | D25: ja | E25: =SUMIFS(Dagschema!$H$2:$H$190,Dagschema!$C$2:$C$190,A25) -> 28.8 | F25: =_xlfn.MAXIFS(Dagschema!$H$2:$H$190,Dagschema!$C$2:$C$190,A25) -> 13.5 | G25: Rustig 6 km + strides | H25: =SUMIFS(Dagschema!$I$2:$I$190,Dagschema!$C$2:$C$190,A25) -> 120 | I25: =SUMIFS(Dagschema!$K$2:$K$190,Dagschema!$C$2:$C$190,A25) -> 0 | J25: =IF(I25=0,"",I25/E25) | K25: =COUNTIFS(Dagschema!$C$2:$C$190,A25,Dagschema!$J$2:$J$190,"x") -> 0 | L25: =COUNTIFS(Dagschema!$C$2:$C$190,A25,Dagschema!$E$2:$E$190,"<>Rust") -> 6
A26: 25 | B26: 46482 | C26: 3 · Specifiek | E26: =SUMIFS(Dagschema!$H$2:$H$190,Dagschema!$C$2:$C$190,A26) -> 41.7 | F26: =_xlfn.MAXIFS(Dagschema!$H$2:$H$190,Dagschema!$C$2:$C$190,A26) -> 16 | G26: Wedstrijdtempo 2×4 km | H26: =SUMIFS(Dagschema!$I$2:$I$190,Dagschema!$C$2:$C$190,A26) -> 120 | I26: =SUMIFS(Dagschema!$K$2:$K$190,Dagschema!$C$2:$C$190,A26) -> 0 | J26: =IF(I26=0,"",I26/E26) | K26: =COUNTIFS(Dagschema!$C$2:$C$190,A26,Dagschema!$J$2:$J$190,"x") -> 0 | L26: =COUNTIFS(Dagschema!$C$2:$C$190,A26,Dagschema!$E$2:$E$190,"<>Rust") -> 7
A27: 26 | B27: 46489 | C27: 4 · Taper | E27: =SUMIFS(Dagschema!$H$2:$H$190,Dagschema!$C$2:$C$190,A27) -> 32.7 | F27: =_xlfn.MAXIFS(Dagschema!$H$2:$H$190,Dagschema!$C$2:$C$190,A27) -> 12 | G27: Interval 4×1 km (taper) | H27: =SUMIFS(Dagschema!$I$2:$I$190,Dagschema!$C$2:$C$190,A27) -> 120 | I27: =SUMIFS(Dagschema!$K$2:$K$190,Dagschema!$C$2:$C$190,A27) -> 0 | J27: =IF(I27=0,"",I27/E27) | K27: =COUNTIFS(Dagschema!$C$2:$C$190,A27,Dagschema!$J$2:$J$190,"x") -> 0 | L27: =COUNTIFS(Dagschema!$C$2:$C$190,A27,Dagschema!$E$2:$E$190,"<>Rust") -> 6
A28: 27 | B28: 46496 | C28: 4 · Taper | E28: =SUMIFS(Dagschema!$H$2:$H$190,Dagschema!$C$2:$C$190,A28) -> 31.4 | F28: =_xlfn.MAXIFS(Dagschema!$H$2:$H$190,Dagschema!$C$2:$C$190,A28) -> 16.1 | G28: Wedstrijdtempo 3×1 km | H28: =SUMIFS(Dagschema!$I$2:$I$190,Dagschema!$C$2:$C$190,A28) -> 60 | I28: =SUMIFS(Dagschema!$K$2:$K$190,Dagschema!$C$2:$C$190,A28) -> 0 | J28: =IF(I28=0,"",I28/E28) | K28: =COUNTIFS(Dagschema!$C$2:$C$190,A28,Dagschema!$J$2:$J$190,"x") -> 0 | L28: =COUNTIFS(Dagschema!$C$2:$C$190,A28,Dagschema!$E$2:$E$190,"<>Rust") -> 5
A29: Totaal | E29: =SUM(E2:E28) -> 776.8 | H29: =SUM(H2:H28) -> 3180 | I29: =SUM(I2:I28) -> 0 | K29: =SUM(K2:K28) -> 0 | L29: =SUM(L2:L28) -> 180
A31: Gepland en gedaan worden automatisch berekend uit de tab Dagschema. Vul daar je km en een x in.

Sheet Dagschema
A1: Datum | B1: Dag | C1: Week | D1: Fase | E1: Sport | F1: Polar-favoriet | G1: Omschrijving | H1: Gepland km lopen | I1: Fiets km (pendel) | J1: Gedaan (x) | K1: Gelopen km | L1: Notities
A2: 46314 | B2: maandag | C2: 1 | D2: 1 · Basis | E2: Lopen | F2: Rustig 4 km | G2: Opwarmen 1,0 km → Rustig 3,0 km | H2: 4
A3: 46315 | B3: dinsdag | C3: 1 | D3: 1 · Basis | E3: Fietsen | F3: — | G3: Pendel Aalter–Gent heen en terug (±60 km). Rustig rijden: HR-zone 1–2, niet koersen. Geen pendel? Rust of 45–60' rustig fietsen. | I3: 60
A4: 46316 | B4: woensdag | C4: 1 | D4: 1 · Basis | E4: Lopen | F4: Rustig 4 km | G4: Opwarmen 1,0 km → Rustig 3,0 km | H4: 4
A5: 46317 | B5: donderdag | C5: 1 | D5: 1 · Basis | E5: Kracht | F5: — | G5: Krachtroutine (±25') – zie tab Uitleg.
A6: 46318 | B6: vrijdag | C6: 1 | D6: 1 · Basis | E6: Fietsen | F6: — | G6: Pendel Aalter–Gent heen en terug (±60 km). Rustig rijden: HR-zone 1–2, niet koersen. Geen pendel? Rust of 45–60' rustig fietsen. | I6: 60
A7: 46319 | B7: zaterdag | C7: 1 | D7: 1 · Basis | E7: Kracht | F7: — | G7: Krachtroutine (±25'). Optioneel: rustige fietstocht max. 90' in HR-zone 1–2.
A8: 46320 | B8: zondag | C8: 1 | D8: 1 · Basis | E8: Lopen | F8: Lange duurloop 7 km | G8: Opwarmen 1,0 km → Duurloop 6,0 km | H8: 7
A9: 46321 | B9: maandag | C9: 2 | D9: 1 · Basis | E9: Lopen | F9: Rustig 4 km | G9: Opwarmen 1,0 km → Rustig 3,0 km | H9: 4
A10: 46322 | B10: dinsdag | C10: 2 | D10: 1 · Basis | E10: Fietsen | F10: — | G10: Pendel Aalter–Gent heen en terug (±60 km). Rustig rijden: HR-zone 1–2, niet koersen. Geen pendel? Rust of 45–60' rustig fietsen. | I10: 60
A11: 46323 | B11: woensdag | C11: 2 | D11: 1 · Basis | E11: Lopen | F11: Rustig 5 km + strides | G11: Opwarmen 1,0 km → Rustig 2,5 km → Stride 0:20 → Herstel 1:00 → Uitlopen 0,5 km | H11: 5.3
A12: 46324 | B12: donderdag | C12: 2 | D12: 1 · Basis | E12: Kracht | F12: — | G12: Krachtroutine (±25') – zie tab Uitleg.
A13: 46325 | B13: vrijdag | C13: 2 | D13: 1 · Basis | E13: Fietsen | F13: — | G13: Pendel Aalter–Gent heen en terug (±60 km). Rustig rijden: HR-zone 1–2, niet koersen. Geen pendel? Rust of 45–60' rustig fietsen. | I13: 60
A14: 46326 | B14: zaterdag | C14: 2 | D14: 1 · Basis | E14: Kracht | F14: — | G14: Krachtroutine (±25'). Optioneel: rustige fietstocht max. 90' in HR-zone 1–2.
A15: 46327 | B15: zondag | C15: 2 | D15: 1 · Basis | E15: Lopen | F15: Lange duurloop 8 km | G15: Opwarmen 1,0 km → Duurloop 7,0 km | H15: 8
A16: 46328 | B16: maandag | C16: 3 | D16: 1 · Basis | E16: Lopen | F16: Rustig 5 km | G16: Opwarmen 1,0 km → Rustig 4,0 km | H16: 5
A17: 46329 | B17: dinsdag | C17: 3 | D17: 1 · Basis | E17: Fietsen | F17: — | G17: Pendel Aalter–Gent heen en terug (±60 km). Rustig rijden: HR-zone 1–2, niet koersen. Geen pendel? Rust of 45–60' rustig fietsen. | I17: 60
A18: 46330 | B18: woensdag | C18: 3 | D18: 1 · Basis | E18: Lopen | F18: Rustig 5 km + strides | G18: Opwarmen 1,0 km → Rustig 2,5 km → Stride 0:20 → Herstel 1:00 → Uitlopen 0,5 km | H18: 5.3
A19: 46331 | B19: donderdag | C19: 3 | D19: 1 · Basis | E19: Kracht | F19: — | G19: Krachtroutine (±25') – zie tab Uitleg.
A20: 46332 | B20: vrijdag | C20: 3 | D20: 1 · Basis | E20: Fietsen | F20: — | G20: Pendel Aalter–Gent heen en terug (±60 km). Rustig rijden: HR-zone 1–2, niet koersen. Geen pendel? Rust of 45–60' rustig fietsen. | I20: 60
A21: 46333 | B21: zaterdag | C21: 3 | D21: 1 · Basis | E21: Kracht | F21: — | G21: Krachtroutine (±25'). Optioneel: rustige fietstocht max. 90' in HR-zone 1–2.
A22: 46334 | B22: zondag | C22: 3 | D22: 1 · Basis | E22: Lopen | F22: Lange duurloop 9 km | G22: Opwarmen 1,0 km → Duurloop 8,0 km | H22: 9
A23: 46335 | B23: maandag | C23: 4 | D23: 1 · Basis | E23: Lopen | F23: Rustig 4 km | G23: Opwarmen 1,0 km → Rustig 3,0 km | H23: 4
A24: 46336 | B24: dinsdag | C24: 4 | D24: 1 · Basis | E24: Fietsen | F24: — | G24: Pendel Aalter–Gent heen en terug (±60 km). Rustig rijden: HR-zone 1–2, niet koersen. Geen pendel? Rust of 45–60' rustig fietsen. | I24: 60
A25: 46337 | B25: woensdag | C25: 4 | D25: 1 · Basis | E25: Lopen | F25: Rustig 4 km | G25: Opwarmen 1,0 km → Rustig 3,0 km | H25: 4
A26: 46338 | B26: donderdag | C26: 4 | D26: 1 · Basis | E26: Kracht | F26: — | G26: Krachtroutine (±25') – zie tab Uitleg.
A27: 46339 | B27: vrijdag | C27: 4 | D27: 1 · Basis | E27: Fietsen | F27: — | G27: Pendel Aalter–Gent heen en terug (±60 km). Rustig rijden: HR-zone 1–2, niet koersen. Geen pendel? Rust of 45–60' rustig fietsen. | I27: 60
A28: 46340 | B28: zaterdag | C28: 4 | D28: 1 · Basis | E28: Rust | F28: — | G28: Rustdag (wandelen mag).
A29: 46341 | B29: zondag | C29: 4 | D29: 1 · Basis | E29: Lopen | F29: Lange duurloop 7 km | G29: Opwarmen 1,0 km → Duurloop 6,0 km | H29: 7
A30: 46342 | B30: maandag | C30: 5 | D30: 1 · Basis | E30: Lopen | F30: Rustig 5 km | G30: Opwarmen 1,0 km → Rustig 4,0 km | H30: 5
A31: 46343 | B31: dinsdag | C31: 5 | D31: 1 · Basis | E31: Fietsen | F31: — | G31: Pendel Aalter–Gent heen en terug (±60 km). Rustig rijden: HR-zone 1–2, niet koersen. Geen pendel? Rust of 45–60' rustig fietsen. | I31: 60
A32: 46344 | B32: woensdag | C32: 5 | D32: 1 · Basis | E32: Lopen | F32: Rustig 6 km + strides | G32: Opwarmen 1,0 km → Rustig 3,5 km → Stride 0:20 → Herstel 1:00 → Uitlopen 0,5 km | H32: 6.3
A33: 46345 | B33: donderdag | C33: 5 | D33: 1 · Basis | E33: Kracht | F33: — | G33: Krachtroutine (±25') – zie tab Uitleg.
A34: 46346 | B34: vrijdag | C34: 5 | D34: 1 · Basis | E34: Fietsen | F34: — | G34: Pendel Aalter–Gent heen en terug (±60 km). Rustig rijden: HR-zone 1–2, niet koersen. Geen pendel? Rust of 45–60' rustig fietsen. | I34: 60
A35: 46347 | B35: zaterdag | C35: 5 | D35: 1 · Basis | E35: Kracht | F35: — | G35: Krachtroutine (±25'). Optioneel: rustige fietstocht max. 90' in HR-zone 1–2.
A36: 46348 | B36: zondag | C36: 5 | D36: 1 · Basis | E36: Lopen | F36: Lange duurloop 10 km | G36: Opwarmen 1,0 km → Duurloop 9,0 km | H36: 10
A37: 46349 | B37: maandag | C37: 6 | D37: 1 · Basis | E37: Lopen | F37: Rustig 5 km | G37: Opwarmen 1,0 km → Rustig 4,0 km | H37: 5
A38: 46350 | B38: dinsdag | C38: 6 | D38: 1 · Basis | E38: Fietsen | F38: — | G38: Pendel Aalter–Gent heen en terug (±60 km). Rustig rijden: HR-zone 1–2, niet koersen. Geen pendel? Rust of 45–60' rustig fietsen. | I38: 60
A39: 46351 | B39: woensdag | C39: 6 | D39: 1 · Basis | E39: Lopen | F39: Fartlek 8×1' (6 km) | G39: Opwarmen 2,0 km → Stevig 1:00 → Rustig 1:00 → Uitlopen 1,4 km | H39: 6
A40: 46352 | B40: donderdag | C40: 6 | D40: 1 · Basis | E40: Kracht | F40: — | G40: Krachtroutine (±25') – zie tab Uitleg.
...

Sheet Polar trainingen
A1: Trainingen om als gefaseerde favoriet in Polar Flow aan te maken
A2: Naam = favorietnaam in Polar Flow. Fasen in deze volgorde invoeren. Tempo- en hartslagzones: zie tab Uitleg.
A4: Rustig 4 km | D4: Totaal ± | E4: 4
A5: Eerste keer: | B5: 46314 | C5: Aantal keer: | D5: =COUNTIF(Dagschema!$F$2:$F$190,"Rustig 4 km") -> 8
A6: Fase | B6: Naam | C6: Type | D6: Duur/afstand | E6: Doel in Polar | F6: Toelichting
A7: 1 | B7: Opwarmen | C7: Afstand | D7: 1,0 km | E7: HR-zone 1–2 | F7: Heel rustig vertrekken, 6:45–7:15/km
A8: 2 | B8: Rustig | C8: Afstand | D8: 3,0 km | E8: HR-zone 2 | F8: Babbeltempo, 6:20–6:50/km, HR 125–137
A10: Lange duurloop 7 km | D10: Totaal ± | E10: 7
A11: Eerste keer: | B11: 46320 | C11: Aantal keer: | D11: =COUNTIF(Dagschema!$F$2:$F$190,"Lange duurloop 7 km") -> 2
A12: Fase | B12: Naam | C12: Type | D12: Duur/afstand | E12: Doel in Polar | F12: Toelichting
A13: 1 | B13: Opwarmen | C13: Afstand | D13: 1,0 km | E13: HR-zone 1–2 | F13: Rustig vertrekken
A14: 2 | B14: Duurloop | C14: Afstand | D14: 6,0 km | E14: HR-zone 2 | F14: Gelijkmatig 6:20–6:50/km; drinken vanaf 75'
A16: Rustig 5 km + strides | D16: Totaal ± | E16: 5.3
A17: Eerste keer: | B17: 46323 | C17: Aantal keer: | D17: =COUNTIF(Dagschema!$F$2:$F$190,"Rustig 5 km + strides") -> 3
A18: Fase | B18: Naam | C18: Type | D18: Duur/afstand | E18: Doel in Polar | F18: Toelichting
A19: 1 | B19: Opwarmen | C19: Afstand | D19: 1,0 km | E19: HR-zone 1–2 | F19: Heel rustig vertrekken
A20: 2 | B20: Rustig | C20: Afstand | D20: 2,5 km | E20: HR-zone 2 | F20: 6:20–6:50/km
A21: 3 | B21: Herhaal 6× | C21: Herhaling | D21: 6× | E21: — | F21: Herhaal fasen 4–5 zes keer
A22: 4 | B22: Stride | C22: Tijd | D22: 0:20 | E22: Vrij | F22: Ontspannen versnellen tot ±4:45/km, niet sprinten
A23: 5 | B23: Herstel | C23: Tijd | D23: 1:00 | E23: HR-zone 1 | F23: Wandelen of heel traag joggen
A24: 6 | B24: Uitlopen | C24: Afstand | D24: 0,5 km | E24: HR-zone 1–2 | F24: Rustig uitlopen
A26: Lange duurloop 8 km | D26: Totaal ± | E26: 8
A27: Eerste keer: | B27: 46327 | C27: Aantal keer: | D27: =COUNTIF(Dagschema!$F$2:$F$190,"Lange duurloop 8 km") -> 1
A28: Fase | B28: Naam | C28: Type | D28: Duur/afstand | E28: Doel in Polar | F28: Toelichting
A29: 1 | B29: Opwarmen | C29: Afstand | D29: 1,0 km | E29: HR-zone 1–2 | F29: Rustig vertrekken
A30: 2 | B30: Duurloop | C30: Afstand | D30: 7,0 km | E30: HR-zone 2 | F30: Gelijkmatig 6:20–6:50/km; drinken vanaf 75'
A32: Rustig 5 km | D32: Totaal ± | E32: 5
A33: Eerste keer: | B33: 46328 | C33: Aantal keer: | D33: =COUNTIF(Dagschema!$F$2:$F$190,"Rustig 5 km") -> 14
A34: Fase | B34: Naam | C34: Type | D34: Duur/afstand | E34: Doel in Polar | F34: Toelichting
A35: 1 | B35: Opwarmen | C35: Afstand | D35: 1,0 km | E35: HR-zone 1–2 | F35: Heel rustig vertrekken, 6:45–7:15/km
A36: 2 | B36: Rustig | C36: Afstand | D36: 4,0 km | E36: HR-zone 2 | F36: Babbeltempo, 6:20–6:50/km, HR 125–137
A38: Lange duurloop 9 km | D38: Totaal ± | E38: 9
A39: Eerste keer: | B39: 46334 | C39: Aantal keer: | D39: =COUNTIF(Dagschema!$F$2:$F$190,"Lange duurloop 9 km") -> 2
A40: Fase | B40: Naam | C40: Type | D40: Duur/afstand | E40: Doel in Polar | F40: Toelichting
A41: 1 | B41: Opwarmen | C41: Afstand | D41: 1,0 km | E41: HR-zone 1–2 | F41: Rustig vertrekken
A42: 2 | B42: Duurloop | C42: Afstand | D42: 8,0 km | E42: HR-zone 2 | F42: Gelijkmatig 6:20–6:50/km; drinken vanaf 75'
A44: Rustig 6 km + strides | D44: Totaal ± | E44: 6.3
A45: Eerste keer: | B45: 46344 | C45: Aantal keer: | D45: =COUNTIF(Dagschema!$F$2:$F$190,"Rustig 6 km + strides") -> 6
A46: Fase | B46: Naam | C46: Type | D46: Duur/afstand | E46: Doel in Polar | F46: Toelichting
A47: 1 | B47: Opwarmen | C47: Afstand | D47: 1,0 km | E47: HR-zone 1–2 | F47: Heel rustig vertrekken
...
